<?xml version="1.0" ?>
<!-- =================================================================================== -->
<!-- |    This document was autogenerated by xacro from lwr.urdf.xacro                 | -->
<!-- |    EDITING THIS FILE BY HAND IS NOT RECOMMENDED                                 | -->
<!-- =================================================================================== -->
<robot name="lwr" xmlns:controller="http://playerstage.sourceforge.net/gazebo/xmlschema/#controller" xmlns:interface="http://playerstage.sourceforge.net/gazebo/xmlschema/#interface" xmlns:sensor="http://playerstage.sourceforge.net/gazebo/xmlschema/#sensor" xmlns:xacro="http://www.ros.org/wiki/xacro">
  <gazebo>
    <plugin filename="librtt_gazebo_plugin.so" name="rtt_gazebo">
      <opsScript>
        import(&quot;rtt_ros&quot;);
        ros.import(&quot;rtt_roscomm&quot;);
        ros.import(&quot;rtt_rosparam&quot;);
        ros.import(&quot;rtt_sensor_msgs&quot;);
        ros.import(&quot;lwr_simulation&quot;);
        ros.import(&quot;oro_joint_state_publisher&quot;);
        
        loadComponent(&quot;FRI&quot;,&quot;LWRController&quot;);
        loadComponent(&quot;joints&quot;,&quot;JointStatePublisher&quot;);
        
        loadService(&quot;FRI&quot;,&quot;rosparam&quot;);
        loadService(&quot;joints&quot;,&quot;rosparam&quot;);
        
        setActivity(&quot;FRI&quot;, 0.0, 5, ORO_SCHED_RT);
        setActivity(&quot;joints&quot;, 0.02, 5, ORO_SCHED_RT);
        
        connect(&quot;FRI.JointPosition&quot;,&quot;joints.msrJntPos&quot;, ConnPolicy());
        stream(&quot;joints.joints_state&quot;, rostopic.connection(&quot;/joints_state&quot;));
        
        joints.rosparam.refreshProperties();
        joints.configure();
        joints.start();
      </opsScript>
      <component>FRI</component>
    </plugin>
  </gazebo>
  <material name="DarkGrey">
    <color rgba="0.3 0.3 0.3 1.0"/>
  </material>
  <material name="Red">
    <color rgba="0.3 0.3 0.3 1.0"/>
  </material>
  <material name="Black">
    <color rgba="0 0 0 1.0"/>
  </material>
  <material name="Orange">
    <color rgba="1.0 0.487 0 1.0"/>
  </material>
  <material name="Silver">
    <color rgba="1.0 1.0 1.0 1.0"/>
  </material>
  <material name="Grey">
    <color rgba="0.7 0.7 0.7 1.0"/>
  </material>
  <material name="Blue">
    <color rgba="0.0 0.0 0.8 1.0"/>
  </material>
  <material name="HandGray">
    <color rgba="0.953 0.996 0.694 1.0"/>
  </material>
  <material name="SickBlue">
    <color rgba="0.3058 0.5921 0.7294 1.0"/>
  </material>
  <link name="table">
    <visual>
      <origin rpy="0 0 0" xyz="0 0 -0.02"/>
      <geometry>
        <box size="0.7 0.75 0.04"/>
      </geometry>
      <material name="table_brown">
        <!-- wooden brown table -->
        <color rgba="0.839215686 0.694117647 0.42745098 1.0"/>
      </material>
    </visual>
    <collision>
      <origin rpy="0 0 0" xyz="0 0 -0.02"/>
      <geometry>
        <box size="0.7 0.75 0.04"/>
      </geometry>
    </collision>
  </link>
  <gazebo reference="table">
    <!-- Gazebo wood texture -->
    <material>Gazebo/Wood</material>
  </gazebo>
  <joint name="table_lwr_arm_base_joint" type="fixed">
    <origin rpy="0 0 0" xyz="0 0 0"/>
    <parent link="table"/>
    <child link="base"/>
  </joint>
  <link name="base">
    <inertial>
      <mass value="2.0"/>
      <origin xyz="0 0 0.055"/>
      <inertia ixx="0.00381666666667" ixy="0" ixz="0" iyy="0.0036" iyz="0" izz="0.00381666666667"/>
    </inertial>
    <visual>
      <origin rpy="0 0 3.14159265359" xyz="0 0 0"/>
      <geometry>
        <mesh filename="package://kuka_lwr4_description/meshes/kuka_colour/base.dae"/>
      </geometry>
      <material name="Blue"/>
    </visual>
    <collision>
      <origin rpy="0 0 0" xyz="0.04 0 0.03"/>
      <geometry>
        <box size="0.08 0.12 0.06"/>
      </geometry>
    </collision>
    <collision>
      <origin rpy="0 0 0" xyz="0 0 0.05"/>
      <geometry>
        <cylinder length="0.1" radius="0.06"/>
      </geometry>
    </collision>
  </link>
  <gazebo reference="calib_lwr_arm_base_link">
    <turnGravityOff>true</turnGravityOff>
  </gazebo>
  <joint name="lwr_arm_0_joint" type="revolute">
    <origin rpy="0 0 3.14159265359" xyz="0 0 0.11"/>
    <axis xyz="0 0 1"/>
    <limit effort="176" lower="-2.96705972839" upper="2.96705972839" velocity="1.91986217719"/>
    <safety_controller k_position="30" k_velocity="30" soft_lower_limit="-2.93215314335" soft_upper_limit="2.93215314335"/>
    <dynamics damping="1.0"/>
    <parent link="base"/>
    <child link="lwr_arm_1_link"/>
  </joint>
  <link name="lwr_arm_1_link">
    <inertial>
      <mass value="2.0"/>
      <origin rpy="0 0 0" xyz="0 -0.06 0.130"/>
      <inertia ixx="0.0136666666667" ixy="0" ixz="0" iyy="0.003" iyz="0" izz="0.0118666666667"/>
    </inertial>
    <visual>
      <origin rpy="0 0 4.71238898038" xyz="0 0 0.2"/>
      <geometry>
        <mesh filename="package://kuka_lwr4_description/meshes/kuka_colour/link1.dae"/>
      </geometry>
      <material name="Blue"/>
    </visual>
    <visual>
      <origin rpy="0 0 4.71238898038" xyz="0 0 0.2"/>
      <geometry>
        <mesh filename="package://kuka_lwr4_description/meshes/kuka_colour/link1_m.dae"/>
      </geometry>
      <material name="Grey"/>
    </visual>
    <visual>
      <origin rpy="0 0 0" xyz="0 0 0"/>
      <geometry>
        <mesh filename="package://kuka_lwr4_description/meshes/kuka_colour/kuka_ring.dae"/>
      </geometry>
      <material name="Grey"/>
    </visual>
    <collision>
      <origin rpy="0 0 0" xyz="0 0 0.05"/>
      <geometry>
        <cylinder length="0.1" radius="0.06"/>
      </geometry>
    </collision>
    <collision>
      <origin rpy="0 0 0" xyz="0 -0.04 0.2"/>
      <geometry>
        <sphere radius="0.06"/>
      </geometry>
    </collision>
  </link>
  <gazebo reference="lwr_arm_1_link">
    <gravity>0</gravity>
  </gazebo>
  <transmission name="lwr_arm_0_trans" type="SimpleTransmission">
    <actuator name="lwr_arm_0_motor"/>
    <joint name="lwr_arm_0_joint"/>
    <mechanicalReduction>1.0</mechanicalReduction>
  </transmission>
  <!-- Third segment of the arm. Joint along y-axis -->
  <joint name="lwr_arm_1_joint" type="revolute">
    <origin rpy="0 0 0" xyz="0 0 0.2"/>
    <axis xyz="0 1 0"/>
    <limit effort="176" lower="-2.09439510239" upper="2.09439510239" velocity="1.91986217719"/>
    <safety_controller k_position="30" k_velocity="30" soft_lower_limit="-2.05948851735" soft_upper_limit="2.05948851735"/>
    <dynamics damping="1.0" friction="10"/>
    <parent link="lwr_arm_1_link"/>
    <child link="lwr_arm_2_link"/>
  </joint>
  <link name="lwr_arm_2_link">
    <inertial>
      <mass value="2.0"/>
      <origin rpy="0 0 0" xyz="0 0.06 0.07"/>
      <inertia ixx="0.0136666666667" ixy="0" ixz="0" iyy="0.003" iyz="0" izz="0.0118666666667"/>
    </inertial>
    <visual>
      <origin rpy="0 0 4.71238898038" xyz="0 0 0"/>
      <geometry>
        <mesh filename="package://kuka_lwr4_description/meshes/kuka_colour/link2.dae"/>
      </geometry>
      <material name="Blue"/>
    </visual>
    <visual>
      <origin rpy="0 0 4.71238898038" xyz="0 0 0"/>
      <geometry>
        <mesh filename="package://kuka_lwr4_description/meshes/kuka_colour/link2_m.dae"/>
      </geometry>
      <material name="Grey"/>
    </visual>
    <visual>
      <origin rpy="1.57079632679 0 0" xyz="0 0 0"/>
      <geometry>
        <mesh filename="package://kuka_lwr4_description/meshes/kuka_colour/kuka_ring.dae"/>
      </geometry>
      <material name="Grey"/>
    </visual>
    <collision>
      <origin rpy="0 0 0" xyz="0 0 0.15"/>
      <geometry>
        <cylinder length="0.1" radius="0.06"/>
      </geometry>
    </collision>
    <collision>
      <origin rpy="0 0 0" xyz="0 0.04 0"/>
      <geometry>
        <sphere radius="0.06"/>
      </geometry>
    </collision>
  </link>
  <gazebo reference="lwr_arm_2_link">
    <gravity>0</gravity>
  </gazebo>
  <transmission name="lwr_arm_1_trans" type="SimpleTransmission">
    <actuator name="lwr_arm_1_motor"/>
    <joint name="lwr_arm_1_joint"/>
    <mechanicalReduction>1.0</mechanicalReduction>
  </transmission>
  <joint name="lwr_arm_2_joint" type="revolute">
    <origin rpy="0 0 0" xyz="0 0 0.20"/>
    <axis xyz="0 0 1"/>
    <limit effort="100" lower="-2.96705972839" upper="2.96705972839" velocity="2.26892802759"/>
    <safety_controller k_position="30" k_velocity="30" soft_lower_limit="-2.93215314335" soft_upper_limit="2.93215314335"/>
    <dynamics damping="1.0"/>
    <parent link="lwr_arm_2_link"/>
    <child link="lwr_arm_3_link"/>
  </joint>
  <link name="lwr_arm_3_link">
    <inertial>
      <mass value="2.0"/>
      <origin rpy="0 0 0" xyz="0 0.06 0.130"/>
      <inertia ixx="0.0136666666667" ixy="0" ixz="0" iyy="0.003" iyz="0" izz="0.0118666666667"/>
    </inertial>
    <visual>
      <origin rpy="0 0 4.71238898038" xyz="0 0 0.2"/>
      <geometry>
        <mesh filename="package://kuka_lwr4_description/meshes/kuka_colour/link3.dae"/>
      </geometry>
      <material name="Blue"/>
    </visual>
    <visual>
      <origin rpy="0 0 4.71238898038" xyz="0 0 0.2"/>
      <geometry>
        <mesh filename="package://kuka_lwr4_description/meshes/kuka_colour/link3_m.dae"/>
      </geometry>
      <material name="Grey"/>
    </visual>
    <visual>
      <origin rpy="0 0 0" xyz="0 0 0"/>
      <geometry>
        <mesh filename="package://kuka_lwr4_description/meshes/kuka_colour/kuka_ring.dae"/>
      </geometry>
      <material name="Grey"/>
    </visual>
    <collision>
      <origin rpy="0 0 0" xyz="0 0 0.05"/>
      <geometry>
        <cylinder length="0.1" radius="0.06"/>
      </geometry>
    </collision>
    <collision>
      <origin rpy="0 0 0" xyz="0 0.04 0.2"/>
      <geometry>
        <sphere radius="0.06"/>
      </geometry>
    </collision>
  </link>
  <gazebo reference="lwr_arm_3_link">
    <turnGravityOff>true</turnGravityOff>
  </gazebo>
  <transmission name="lwr_arm_2_trans" type="SimpleTransmission">
    <actuator name="lwr_arm_2_motor"/>
    <joint name="lwr_arm_2_joint"/>
    <mechanicalReduction>1.0</mechanicalReduction>
  </transmission>
  <!-- fifth element of the arm. x-axis -->
  <joint name="lwr_arm_3_joint" type="revolute">
    <origin rpy="0 0 0" xyz="0 0 0.20"/>
    <axis xyz="0 -1 0"/>
    <limit effort="100" lower="-2.09439510239" upper="2.09439510239" velocity="2.26892802759"/>
    <safety_controller k_position="30" k_velocity="30" soft_lower_limit="-2.05948851735" soft_upper_limit="2.05948851735"/>
    <dynamics damping="1.0"/>
    <parent link="lwr_arm_3_link"/>
    <child link="lwr_arm_4_link"/>
  </joint>
  <link name="lwr_arm_4_link">
    <inertial>
      <mass value="2.0"/>
      <origin rpy="0 0 0" xyz="0 -0.06 0.07"/>
      <inertia ixx="0.0136666666667" ixy="0" ixz="0" iyy="0.003" iyz="0" izz="0.0118666666667"/>
    </inertial>
    <visual>
      <origin rpy="0 0 4.71238898038" xyz="0 0 0"/>
      <geometry>
        <mesh filename="package://kuka_lwr4_description/meshes/kuka_colour/link4.dae"/>
      </geometry>
      <material name="Blue"/>
    </visual>
    <visual>
      <origin rpy="0 0 4.71238898038" xyz="0 0 0"/>
      <geometry>
        <mesh filename="package://kuka_lwr4_description/meshes/kuka_colour/link4_m.dae"/>
      </geometry>
      <material name="Grey"/>
    </visual>
    <visual>
      <origin rpy="1.57079632679 0 0" xyz="0 0 0"/>
      <geometry>
        <mesh filename="package://kuka_lwr4_description/meshes/kuka_colour/kuka_ring.dae"/>
      </geometry>
      <material name="Grey"/>
    </visual>
    <collision>
      <origin rpy="0 0 0" xyz="0 0 0.15"/>
      <geometry>
        <cylinder length="0.1" radius="0.06"/>
      </geometry>
    </collision>
    <collision>
      <origin rpy="0 0 0" xyz="0 -0.04 0"/>
      <geometry>
        <sphere radius="0.06"/>
      </geometry>
    </collision>
  </link>
  <gazebo reference="lwr_arm_4_link">
    <turnGravityOff>true</turnGravityOff>
  </gazebo>
  <transmission name="lwr_arm_3_trans" type="SimpleTransmission">
    <actuator name="lwr_arm_3_motor"/>
    <joint name="lwr_arm_3_joint"/>
    <mechanicalReduction>1.0</mechanicalReduction>
  </transmission>
  <joint name="lwr_arm_4_joint" type="revolute">
    <origin rpy="0 0 0" xyz="0 0 0.20"/>
    <axis xyz="0 0 1"/>
    <limit effort="100" lower="-2.96705972839" upper="2.96705972839" velocity="2.26892802759"/>
    <safety_controller k_position="30" k_velocity="30" soft_lower_limit="-2.93215314335" soft_upper_limit="2.93215314335"/>
    <dynamics damping="1.0"/>
    <parent link="lwr_arm_4_link"/>
    <child link="lwr_arm_5_link"/>
  </joint>
  <link name="lwr_arm_5_link">
    <inertial>
      <mass value="2.0"/>
      <origin rpy="0 0 0" xyz="0 0 0.124"/>
      <inertia ixx="0.0126506666667" ixy="0" ixz="0" iyy="0.003" iyz="0" izz="0.0108506666667"/>
    </inertial>
    <visual>
      <origin rpy="0 0 4.71238898038" xyz="0 0 0.19"/>
      <geometry name="lwr_arm_5_geom">
        <mesh filename="package://kuka_lwr4_description/meshes/kuka_colour/link5.dae"/>
      </geometry>
      <material name="Blue"/>
    </visual>
    <visual>
      <origin rpy="0 0 0" xyz="0 0 0"/>
      <geometry>
        <mesh filename="package://kuka_lwr4_description/meshes/kuka_colour/kuka_ring.dae"/>
      </geometry>
      <material name="Grey"/>
    </visual>
    <collision>
      <origin rpy="0 0 0" xyz="0 0 0.05"/>
      <geometry>
        <cylinder length="0.1" radius="0.06"/>
      </geometry>
    </collision>
    <collision>
      <origin rpy="0 0 0" xyz="0 -0.04 0.2"/>
      <geometry>
        <sphere radius="0.06"/>
      </geometry>
    </collision>
  </link>
  <gazebo reference="lwr_arm_5_link">
    <turnGravityOff>true</turnGravityOff>
  </gazebo>
  <transmission name="lwr_arm_4_trans" type="SimpleTransmission">
    <actuator name="lwr_arm_4_motor"/>
    <joint name="lwr_arm_4_joint"/>
    <mechanicalReduction>1.0</mechanicalReduction>
  </transmission>
  <joint name="lwr_arm_5_joint" type="revolute">
    <origin rpy="0 0 0" xyz="0 0 0.19"/>
    <axis xyz="0 1 0"/>
    <limit effort="38" lower="-2.09439510239" upper="2.09439510239" velocity="3.14159265359"/>
    <safety_controller k_position="30" k_velocity="30" soft_lower_limit="-2.05948851735" soft_upper_limit="2.05948851735"/>
    <dynamics damping="1.0"/>
    <parent link="lwr_arm_5_link"/>
    <child link="lwr_arm_6_link"/>
  </joint>
  <link name="lwr_arm_6_link">
    <inertial>
      <mass value="0.2"/>
      <origin rpy="0 0 0" xyz="0 0 0.0625"/>
      <inertia ixx="0.000520833333333" ixy="0" ixz="0" iyy="0.000520833333333" iyz="0" izz="0.000520833333333"/>
    </inertial>
    <visual>
      <origin rpy="0 0 3.14159265359" xyz="0 0 0"/>
      <geometry>
        <mesh filename="package://kuka_lwr4_description/meshes/kuka_colour/kuka_wrist.dae"/>
      </geometry>
      <material name="Grey"/>
    </visual>
    <collision>
      <origin rpy="0 0 0" xyz="0 0.01 0"/>
      <geometry>
        <sphere radius="0.07"/>
      </geometry>
      <material name="Grey"/>
    </collision>
    <collision>
      <origin rpy="0 0 0" xyz="0 -0.01 0"/>
      <geometry>
        <sphere radius="0.07"/>
      </geometry>
    </collision>
  </link>
  <gazebo reference="lwr_arm_6_link">
    <turnGravityOff>true</turnGravityOff>
  </gazebo>
  <transmission name="lwr_arm_5_trans" type="SimpleTransmission">
    <actuator name="lwr_arm_5_motor"/>
    <joint name="lwr_arm_5_joint"/>
    <mechanicalReduction>1.0</mechanicalReduction>
  </transmission>
  <joint name="lwr_arm_6_joint" type="revolute">
    <origin rpy="0 0 3.14159265359" xyz="0 0 0.078"/>
    <axis xyz="0 0 1"/>
    <limit effort="38" lower="-2.96705972839" upper="2.96705972839" velocity="3.14159265359"/>
    <safety_controller k_position="30" k_velocity="30" soft_lower_limit="-2.93215314335" soft_upper_limit="2.93215314335"/>
    <dynamics damping="1.0"/>
    <parent link="lwr_arm_6_link"/>
    <child link="lwr_arm_7_link"/>
  </joint>
  <link name="lwr_arm_7_link">
    <inertial>
      <mass value="0.2"/>
      <origin xyz="0 0 0"/>
      <inertia ixx="0.0333333333333" ixy="0" ixz="0" iyy="0.0333333333333" iyz="0" izz="0.0333333333333"/>
    </inertial>
    <visual>
      <origin rpy="0 0 0" xyz="0 0 0"/>
      <geometry>
        <mesh filename="package://kuka_lwr4_description/meshes/kuka_colour/link7.dae"/>
      </geometry>
      <material name="Grey"/>
    </visual>
    <collision>
      <origin rpy="0 0 -0.785398163397" xyz="0 0 0"/>
      <geometry>
        <cylinder length="0.05" radius="0.04"/>
      </geometry>
    </collision>
  </link>
  <gazebo reference="lwr_arm_7_link">
    <turnGravityOff>true</turnGravityOff>
  </gazebo>
  <transmission name="lwr_arm_6_trans" type="SimpleTransmission">
    <actuator name="lwr_arm_6_motor"/>
    <joint name="lwr_arm_6_joint"/>
    <mechanicalReduction>1.0</mechanicalReduction>
  </transmission>
</robot>

